Traceback (most recent call last):
  File "C:\Users\biagi\anaconda3\envs\book\Lib\site-packages\jupyter_cache\executors\utils.py", line 58, in single_nb_execution
    executenb(
  File "C:\Users\biagi\anaconda3\envs\book\Lib\site-packages\nbclient\client.py", line 1314, in execute
    return NotebookClient(nb=nb, resources=resources, km=km, **kwargs).execute()
           ^^^^^^^^^^^^^^^^^^^^^^^^^^^^^^^^^^^^^^^^^^^^^^^^^^^^^^^^^^^^^^^^^^^^^
  File "C:\Users\biagi\anaconda3\envs\book\Lib\site-packages\jupyter_core\utils\__init__.py", line 165, in wrapped
    return loop.run_until_complete(inner)
           ^^^^^^^^^^^^^^^^^^^^^^^^^^^^^^
  File "C:\Users\biagi\anaconda3\envs\book\Lib\asyncio\base_events.py", line 687, in run_until_complete
    return future.result()
           ^^^^^^^^^^^^^^^
  File "C:\Users\biagi\anaconda3\envs\book\Lib\site-packages\nbclient\client.py", line 709, in async_execute
    await self.async_execute_cell(
  File "C:\Users\biagi\anaconda3\envs\book\Lib\site-packages\nbclient\client.py", line 1062, in async_execute_cell
    await self._check_raise_for_error(cell, cell_index, exec_reply)
  File "C:\Users\biagi\anaconda3\envs\book\Lib\site-packages\nbclient\client.py", line 918, in _check_raise_for_error
    raise CellExecutionError.from_cell_and_msg(cell, exec_reply_content)
nbclient.exceptions.CellExecutionError: An error occurred while executing the following cell:
------------------
import numpy as np
from scipy.spatial.transform import Rotation

m = 60
X = np.zeros((m, 3))  # initialize 3D dataset
np.random.seed(42)
angles = (np.random.rand(m) ** 3 + 0.5) * 2 * np.pi  # uneven distribution
X[:, 0], X[:, 1] = np.cos(angles), np.sin(angles) * 0.5  # oval
X += 0.28 * np.random.randn(m, 3)  # add more noise
X = Rotation.from_rotvec([np.pi / 29, -np.pi / 20, np.pi / 4]).apply(X)
X += [0.2, 0, 0.2]  # shift a bit
------------------


[1;31m---------------------------------------------------------------------------[0m
[1;31mModuleNotFoundError[0m                       Traceback (most recent call last)
Cell [1;32mIn[3], line 2[0m
[0;32m      1[0m [38;5;28;01mimport[39;00m [38;5;21;01mnumpy[39;00m [38;5;28;01mas[39;00m [38;5;21;01mnp[39;00m
[1;32m----> 2[0m [38;5;28;01mfrom[39;00m [38;5;21;01mscipy[39;00m[38;5;21;01m.[39;00m[38;5;21;01mspatial[39;00m[38;5;21;01m.[39;00m[38;5;21;01mtransform[39;00m [38;5;28;01mimport[39;00m Rotation
[0;32m      4[0m m [38;5;241m=[39m [38;5;241m60[39m
[0;32m      5[0m X [38;5;241m=[39m np[38;5;241m.[39mzeros((m, [38;5;241m3[39m))  [38;5;66;03m# initialize 3D dataset[39;00m

[1;31mModuleNotFoundError[0m: No module named 'scipy'

