Traceback (most recent call last):
  File "C:\Users\biagi\anaconda3\envs\book\Lib\site-packages\jupyter_cache\executors\utils.py", line 58, in single_nb_execution
    executenb(
  File "C:\Users\biagi\anaconda3\envs\book\Lib\site-packages\nbclient\client.py", line 1314, in execute
    return NotebookClient(nb=nb, resources=resources, km=km, **kwargs).execute()
           ^^^^^^^^^^^^^^^^^^^^^^^^^^^^^^^^^^^^^^^^^^^^^^^^^^^^^^^^^^^^^^^^^^^^^
  File "C:\Users\biagi\anaconda3\envs\book\Lib\site-packages\jupyter_core\utils\__init__.py", line 165, in wrapped
    return loop.run_until_complete(inner)
           ^^^^^^^^^^^^^^^^^^^^^^^^^^^^^^
  File "C:\Users\biagi\anaconda3\envs\book\Lib\asyncio\base_events.py", line 687, in run_until_complete
    return future.result()
           ^^^^^^^^^^^^^^^
  File "C:\Users\biagi\anaconda3\envs\book\Lib\site-packages\nbclient\client.py", line 709, in async_execute
    await self.async_execute_cell(
  File "C:\Users\biagi\anaconda3\envs\book\Lib\site-packages\nbclient\client.py", line 1062, in async_execute_cell
    await self._check_raise_for_error(cell, cell_index, exec_reply)
  File "C:\Users\biagi\anaconda3\envs\book\Lib\site-packages\nbclient\client.py", line 918, in _check_raise_for_error
    raise CellExecutionError.from_cell_and_msg(cell, exec_reply_content)
nbclient.exceptions.CellExecutionError: An error occurred while executing the following cell:
------------------
import pandas as pd
my_df = pd.DataFrame(data={
    'col_one': range(1, 5),
    'col_two': range(11, 15),
    'col_three': range(21, 25)
}, index = [
    'row_one', 'row_two', 'row_three', 'row_four'
])
display(my_df)
------------------


[1;31m---------------------------------------------------------------------------[0m
[1;31mModuleNotFoundError[0m                       Traceback (most recent call last)
Cell [1;32mIn[1], line 1[0m
[1;32m----> 1[0m [38;5;28;01mimport[39;00m [38;5;21;01mpandas[39;00m [38;5;28;01mas[39;00m [38;5;21;01mpd[39;00m
[0;32m      2[0m my_df [38;5;241m=[39m pd[38;5;241m.[39mDataFrame(data[38;5;241m=[39m{
[0;32m      3[0m     [38;5;124m'[39m[38;5;124mcol_one[39m[38;5;124m'[39m: [38;5;28mrange[39m([38;5;241m1[39m, [38;5;241m5[39m),
[0;32m      4[0m     [38;5;124m'[39m[38;5;124mcol_two[39m[38;5;124m'[39m: [38;5;28mrange[39m([38;5;241m11[39m, [38;5;241m15[39m),
[1;32m   (...)[0m
[0;32m      7[0m     [38;5;124m'[39m[38;5;124mrow_one[39m[38;5;124m'[39m, [38;5;124m'[39m[38;5;124mrow_two[39m[38;5;124m'[39m, [38;5;124m'[39m[38;5;124mrow_three[39m[38;5;124m'[39m, [38;5;124m'[39m[38;5;124mrow_four[39m[38;5;124m'[39m
[0;32m      8[0m ])
[0;32m      9[0m display(my_df)

[1;31mModuleNotFoundError[0m: No module named 'pandas'

