Traceback (most recent call last):
  File "C:\Users\biagi\anaconda3\envs\book\Lib\site-packages\jupyter_cache\executors\utils.py", line 58, in single_nb_execution
    executenb(
  File "C:\Users\biagi\anaconda3\envs\book\Lib\site-packages\nbclient\client.py", line 1305, in execute
    return NotebookClient(nb=nb, resources=resources, km=km, **kwargs).execute()
           ^^^^^^^^^^^^^^^^^^^^^^^^^^^^^^^^^^^^^^^^^^^^^^^^^^^^^^^^^^^^^^^^^^^^^
  File "C:\Users\biagi\anaconda3\envs\book\Lib\site-packages\jupyter_core\utils\__init__.py", line 165, in wrapped
    return loop.run_until_complete(inner)
           ^^^^^^^^^^^^^^^^^^^^^^^^^^^^^^
  File "C:\Users\biagi\anaconda3\envs\book\Lib\asyncio\base_events.py", line 687, in run_until_complete
    return future.result()
           ^^^^^^^^^^^^^^^
  File "C:\Users\biagi\anaconda3\envs\book\Lib\site-packages\nbclient\client.py", line 705, in async_execute
    await self.async_execute_cell(
  File "C:\Users\biagi\anaconda3\envs\book\Lib\site-packages\nbclient\client.py", line 1058, in async_execute_cell
    await self._check_raise_for_error(cell, cell_index, exec_reply)
  File "C:\Users\biagi\anaconda3\envs\book\Lib\site-packages\nbclient\client.py", line 914, in _check_raise_for_error
    raise CellExecutionError.from_cell_and_msg(cell, exec_reply_content)
nbclient.exceptions.CellExecutionError: An error occurred while executing the following cell:
------------------
def get_data(url, presize, resize):
    path = untar_data(url)
    return DataBlock(
        blocks=(ImageBlock, CategoryBlock), get_items=get_image_files, 
        splitter=GrandparentSplitter(valid_name='val'),
        get_y=parent_label, item_tfms=Resize(presize),
        batch_tfms=[*aug_transforms(min_scale=0.5, size=resize),
                    Normalize.from_stats(*imagenet_stats)],
    ).dataloaders(path, bs=64) # Assuming fewer images due to high data complexity

dls = get_data(URLs.MEDICAL_DATASET, 128, 96)
dls.show_batch(max_n=4)
------------------


[1;31m---------------------------------------------------------------------------[0m
[1;31mNameError[0m                                 Traceback (most recent call last)
Cell [1;32mIn[1], line 11[0m
[0;32m      2[0m     path [38;5;241m=[39m untar_data(url)
[0;32m      3[0m     [38;5;28;01mreturn[39;00m DataBlock(
[0;32m      4[0m         blocks[38;5;241m=[39m(ImageBlock, CategoryBlock), get_items[38;5;241m=[39mget_image_files, 
[0;32m      5[0m         splitter[38;5;241m=[39mGrandparentSplitter(valid_name[38;5;241m=[39m[38;5;124m'[39m[38;5;124mval[39m[38;5;124m'[39m),
[1;32m   (...)[0m
[0;32m      8[0m                     Normalize[38;5;241m.[39mfrom_stats([38;5;241m*[39mimagenet_stats)],
[0;32m      9[0m     )[38;5;241m.[39mdataloaders(path, bs[38;5;241m=[39m[38;5;241m64[39m) [38;5;66;03m# Assuming fewer images due to high data complexity[39;00m
[1;32m---> 11[0m dls [38;5;241m=[39m get_data(URLs[38;5;241m.[39mMEDICAL_DATASET, [38;5;241m128[39m, [38;5;241m96[39m)
[0;32m     12[0m dls[38;5;241m.[39mshow_batch(max_n[38;5;241m=[39m[38;5;241m4[39m)

[1;31mNameError[0m: name 'URLs' is not defined

